Workbook

Sheet REPORT DATA SHEET
A1: Report dt 25-06-2026
A2: FINISH STOCK | F2: SALES REPORT | L2: SALES PENDING SOUDA
A3: PRODUCT | B3: KATTA | D3: IN QTL | E3: in% | F3: PRODUCT | G3: KATTA | I3: IN QTL | J3: IN % | K3: AMOUNT | L3: PRODUCT | M3: KATTA | O3: IN QTL | P3: IN % | Q3: AMOUNT
A4: MAIDA BAKERY | C4: 50 | D4: 52 | E4: =(D4*100)/$D$22 -> 72.222222 | F4: MAIDA PREMIUM 50 KG | G4: 12589 | H4: 50 | I4: =+G4*H4/100 -> 6294.5 | J4: =(I4*100)/$I$22 -> 53.701427 | L4: MAIDA PREMIUM 50 KG | N4: 50 | O4: =+M4*N4/100 -> 0 | P4: =+O4/$O$22*100 -> #DIV/0!
A5: MAIDA 30 | C5: 30 | D5: 20 | E5: =(D5*100)/$D$22 -> 27.777778 | F5: MAIDA 30KG | G5: 1465 | H5: 30 | I5: =+G5*H5/100 -> 439.5 | J5: =(I5*100)/$I$22 -> 3.7495873 | L5: MAIDA 30KG | N5: 30 | O5: =+M5*N5/100 -> 0 | P5: =+O5/$O$22*100 -> #DIV/0!
A6: MAIDA LEMINATION 50 KG | D6: =+B6*0.5 -> 0 | E6: =(D6*100)/$D$22 -> 0 | F6: MAIDA LEMINATION 50 KG | G6: 3053 | I6: =+G6*0.5 -> 1526.5 | J6: =(I6*100)/$I$22 -> 13.023311 | L6: MAIDA LEMINATION 50 KG | N6: 50 | O6: =+M6*N6/100 -> 0 | P6: =+O6/$O$22*100 -> #DIV/0! | V6: =+S6*U6/100 -> 0 | W6: BRAN FINE LOOSE | X6: 300
A7: REFINED WHEAT FLOUR (MAIDA) 50KG | C7: 50 | D7: =+B7*C7/100 -> 0 | E7: =(D7*100)/$D$22 -> 0 | F7: REFINED WHEAT FLOUR (MAIDA) 50KG | H7: 50 | I7: =+G7*H7/100 -> 0 | J7: =(I7*100)/$I$22 -> 0 | L7: REFINED WHEAT FLOUR (MAIDA) 50KG | N7: 50 | O7: =+M7*N7/100 -> 0 | P7: =+O7/$O$22*100 -> #DIV/0! | V7: =+S7*U7/100 -> 0 | W7: Bran Fine 49 KG | X7: 715
A8: SOOJI50 | C8: 50 | D8: =+B8*C8/100 -> 0 | E8: =(D8*100)/$D$22 -> 0 | F8: SOOJI 50 KG | G8: 670 | H8: 50 | I8: =+G8*H8/100 -> 335 | J8: =(I8*100)/$I$22 -> 2.8580472 | L8: SOOJI 50 KG | N8: 50 | O8: =+M8*N8/100 -> 0 | P8: =+O8/$O$22*100 -> #DIV/0! | V8: =+S8*U8/100 -> 0 | W8: Bran ROUGH 39 KG-Non Branded | X8: 162
A9: SOOJI30 | C9: 30 | D9: =+B9*C9/100 -> 0 | E9: =(D9*100)/$D$22 -> 0 | F9: Sooji 30 Kgs | G9: 518 | H9: 30 | I9: =+G9*H9/100 -> 155.4 | J9: =(I9*100)/$I$22 -> 1.3257926 | L9: Sooji 30 Kgs | N9: 30 | O9: =+M9*N9/100 -> 0 | P9: =+O9/$O$22*100 -> #DIV/0! | V9: =+S9*U9/100 -> 0 | W9: DELUX BRAN 49KG | X9: 4675
A10: RAWA 50 | C10: 50 | D10: =+B10*C10/100 -> 0 | E10: =(D10*100)/$D$22 -> 0 | F10: Rawa 50 kg | G10: 1588 | H10: 50 | I10: =+G10*H10/100 -> 794 | J10: =(I10*100)/$I$22 -> 6.7739984 | L10: Rawa 50 kg | N10: 50 | O10: =+M10*N10/100 -> 0 | P10: =+O10/$O$22*100 -> #DIV/0! | R10: 0 | V10: =+S10*U10/100 -> 0 | W10: MAIDA 30KG | X10: 450
A11: RAWA 30 | C11: 30 | D11: =+B11*C11/100 -> 0 | E11: =(D11*100)/$D$22 -> 0 | F11: Rawa 30 Kg | G11: 401 | H11: 30 | I11: =+G11*H11/100 -> 120.3 | J11: =(I11*100)/$I$22 -> 1.0263375 | L11: Rawa 30 Kg | N11: 30 | O11: =+M11*N11/100 -> 0 | P11: =+O11/$O$22*100 -> #DIV/0! | V11: =+S11*U11/100 -> 0 | W11: MAIDA PREMIUM 50 KG | X11: 10255
A12: TM50 | C12: 50 | D12: =+B12*C12/100 -> 0 | E12: =(D12*100)/$D$22 -> 0 | F12: TANDORI MAIDA 50 KG | G12: 348 | H12: 50 | I12: =+G12*H12/100 -> 174 | J12: =(I12*100)/$I$22 -> 1.4844782 | L12: TANDORI MAIDA 50 KG | N12: 50 | O12: =+M12*N12/100 -> 0 | P12: =+O12/$O$22*100 -> #DIV/0! | R12: 0 | V12: =+S12*U12/100 -> 0 | W12: MAIZE | X12: 11.85
A13: CA50 | C13: 50 | D13: =+B13*C13/100 -> 0 | E13: =(D13*100)/$D$22 -> 0 | F13: CA50 | H13: 50 | I13: =+G13*H13/100 -> 0 | J13: =(I13*100)/$I$22 -> 0 | L13: CA50 | N13: 50 | O13: =+M13*N13/100 -> 0 | P13: =+O13/$O$22*100 -> #DIV/0! | V13: =+S13*U13/100 -> 0 | W13: Rawa 30 Kg | X13: 1113
A14: CA30 | C14: 30 | D14: =+B14*C14/100 -> 0 | E14: =(D14*100)/$D$22 -> 0 | F14: CA30 | H14: 30 | I14: =+G14*H14/100 -> 0 | J14: =(I14*100)/$I$22 -> 0 | L14: CA30 | N14: 50 | O14: =+M14*N14/100 -> 0 | P14: =+O14/$O$22*100 -> #DIV/0! | V14: =+S14*U14/100 -> 0 | W14: Rawa 50 kg | X14: 410
A15: FINE BRAN 40 KG | C15: 40 | D15: =+B15*C15/100 -> 0 | E15: =(D15*100)/$D$22 -> 0 | F15: FINE BRAN 40 KG | H15: 40 | I15: =+G15*H15/100 -> 0 | J15: =(I15*100)/$I$22 -> 0 | N15: 50 | O15: =+M15*N15/100 -> 0 | P15: =+O15/$O$22*100 -> #DIV/0! | V15: =+S15*U15/100 -> 0 | W15: Sooji 30 Kgs | X15: 684
A16: COURS BRAN | C16: 39 | D16: =+B16*C16/100 -> 0 | E16: =(D16*100)/$D$22 -> 0 | F16: Bran ROUGH 39 KG-Non Branded | H16: 39 | I16: =+G16*0.39 -> 0 | J16: =(I16*100)/$I$22 -> 0 | L16: Bran ROUGH 39 KG-Non Branded | N16: 39 | O16: =+M16*N16/100 -> 0 | P16: =+O16/$O$22*100 -> #DIV/0! | V16: =SUM(V6:V15) -> 0 | W16: SOOJI 50 KG | X16: 1089
A17: FINE BRAN | C17: 49 | D17: =+B17*C17/100 -> 0 | E17: =(D17*100)/$D$22 -> 0 | F17: Bran Fine 49 KG | G17: =1470+340 -> 1810 | H17: 49 | I17: =+G17*H17/100 -> 886.9 | J17: =(I17*100)/$I$22 -> 7.5665733 | L17: Bran Fine 49 KG | N17: 49 | O17: =+M17*N17/100 -> 0 | P17: =+O17/$O$22*100 -> #DIV/0! | W17: TANDORI MAIDA 50 KG | X17: 279
A18: DELUX BRAN | C18: 49 | D18: =+B18*C18/100 -> 0 | E18: =(D18*100)/$D$22 -> 0 | F18: DELUX BRAN 49KG | G18: 2031 | H18: 49 | I18: =+G18*H18/100 -> 995.19 | J18: =(I18*100)/$I$22 -> 8.4904477 | L18: DELUX BRAN 49KG | N18: 49 | O18: =+M18*N18/100 -> 0 | P18: =+O18/$O$22*100 -> #DIV/0!
A19: POWER MESS ( C F ) | C19: 50 | D19: =+B19*C19/100 -> 0 | E19: =(D19*100)/$D$22 -> 0 | F19: POWER MESS ( C F ) | H19: 50 | I19: =+G19*H19/100 -> 0 | J19: =(I19*100)/$I$22 -> 0 | L19: BRAN FINE 40 KG | N19: 40 | O19: =+M19*0.4 -> 0 | P19: =+O19/$O$22*100 -> #DIV/0!
M21: 0 | Q21: 0
A22: TOTAL | B22: =SUM(B4:B19) -> 0 | D22: =SUM(D4:D19) -> 72 | E22: =SUM(E4:E19) -> 100 | F22: TOTAL | G22: =SUM(G4:G19) -> 24473 | I22: =SUM(I4:I19) -> 11721.29 | J22: =SUM(J3:J19) -> 100 | K22: =SUM(K4:K19) -> 0 | L22: TOTAL | M22: =+M21+M20+M19+M18+M17+M16+M15+M14+M13+M12+M11+M10+M9+M8+M7+M6+M5+M4 -> 0 | N22: =SUM(N4:N21) -> 717 | O22: =SUM(O4:O19) -> 0 | P22: =SUM(P4:P19) -> #DIV/0! | Q22: =SUM(Q4:Q19) -> 0
I23: AV RATE | J23: =+K22/I22 -> 0 | M23: SAUDA RATE | O23: =+Q22/O22 -> #DIV/0! | R23: 11911 | S23: =+M22-R23 -> -11911
A25: रिपोर्ट दिनाक | F25: TODAYS PPODUCTION | K25: SALESMAN WISE SALES REPORT
E26: ओसत पिसाई के अनुसार | F26: PRODUCT | G26: KATTA | I26: IN QTL | J26: IN % | K26: Row Labels | L26: ADITYA | M26: KAILASH SHARMA | N26: ADMIN | O26: ADMIN | P26: TOTAL
A27: मिल पिसाई | B27: =I43 -> 414.56 | D27: QTL | F27: MAIDA | G27: 499 | H27: 50 | I27: =G27*50/100 -> 249.5 | J27: =I27/I43*100 -> 60.184292 | K27: MAIDA PREMIUM 50 KG | P27: =O27+M27+L27 -> 0
A28: चक्की पिसाई | B28: 0 | D28: QTL | F28: MAIDA 30 | G28: 0 | H28: 30 | I28: =G28*30/100 -> 0 | J28: =I28/I43*100 -> 0 | K28: MAIDA 30KG | P28: =O28+M28+L28 -> 0
A29: मिल कुल पिसाई | B29: 0 | D29: QTL | F29: MAIDA LEMINATION 50 KG | G29: 0 | H29: 50 | I29: =G29*50/100 -> 0 | J29: =I29/I43*100 -> 0 | K29: REFINED WHEAT FLOUR (MAIDA) 50KG | P29: =O29+M29+L29 -> 0
A30: चक्की कुल पिसाई | B30: 0 | D30: QTL | F30: REFINED WHEAT FLOUR (MAIDA) 50KG | G30: 0 | H30: 50 | I30: =G30*50/100 -> 0 | J30: =I30/I43*100 -> 0 | K30: LEMINATION MAIDA 50 KG | P30: =O30+M30+L30 -> 0 | S30: 0 | T30: 0 | V30: =+VLOOKUP(R30,'june 6'!$A$25:$B$32,2,0) -> #N/A | W30: 0 | X30: =+W30+V30+T30+S30 -> #N/A
A31: टोटल मिल औरचक्की | B31: =G48 -> 414.56 | D31: QTL | F31: SOOJI50 | G31: 35 | H31: 50 | I31: =G31*50/100 -> 17.5 | J31: =I31/I43*100 -> 4.2213431 | K31: SOOJI 50 KG | P31: =O31+M31+L31 -> 0
A32: ओसतपिसाई मिल | B32: =B31/28 -> 14.805714 | D32: QTL PER DAY | F32: SOOJI30 | G32: 0 | H32: 30 | I32: =G32*30/100 -> 0 | J32: =I32/I43*100 -> 0 | K32: Sooji 30 Kgs | P32: =O32+M32+L32 -> 0
A33: ओसतपिसाई चक्की | B33: 0 | D33: QTL PER DAY | E33: =B32*30 -> 444.17143 | F33: RAWA 50 | G33: 56 | H33: 50 | I33: =G33*50/100 -> 28 | J33: =I33/I43*100 -> 6.754149 | K33: Rawa 50 kg | P33: =O33+M33+L33 -> 0
A34: फाइन ब्रान | B34: =J40 -> 9.4558086 | F34: RAWA 30 | G34: 0 | H34: 30 | I34: =G34*30/100 -> 0 | J34: =I34/I43*100 -> 0 | K34: Rawa 30 Kg | P34: =O34+M34+L34 -> 0
A35: सुपर डिलक्स ब्रान | B35: =J42 -> 0 | F35: TM50 | G35: 0 | H35: 50 | I35: =G35*50/100 -> 0 | J35: =I35/I43*100 -> 0 | K35: TANDORI MAIDA 50 KG | P35: =O35+M35+L35 -> 0
A36: डिलक्स ब्रान | B36: =J41 -> 19.384408 | F36: CA50 | G36: 0 | H36: 50 | I36: =G36*50/100 -> 0 | J36: 0 | K36: CA50 | P36: =O36+M36+L36 -> 0
A37: जाड़ा ब्रान | B37: =J39 -> 0 | F37: CA30 | G37: 0 | H37: 30 | I37: =G37*30/100 -> 0 | J37: 0 | K37: CA30 | P37: =O37+M37+L37 -> 0
A38: कुल ब्रान | B38: =SUM(B34:B37) -> 28.840216 | F38: Bran Fine 40 KG | G38: 0 | H38: 40 | I38: =G38*40/100 -> 0 | J38: =I38/I43*100 -> 0 | K38: Bran Fine 40 KG | P38: =O38+M38+L38 -> 0
A39: ब्रान चक्की | B39: 0 | F39: COURS BRAN | G39: 0 | H39: 39 | I39: =G39*39/100 -> 0 | J39: =I39/I43*100 -> 0 | K39: Bran ROUGH 39 KG-Non Branded | P39: =O39+M39+L39 -> 0
A40: लोड | B40: =+B27/G52 -> 30.937313 | F40: FINE BRAN | G40: 80 | H40: 49 | I40: =G40*49/100 -> 39.2 | J40: =I40/I43*100 -> 9.4558086 | K40: Bran Fine 49 KG | P40: =O40+M40+L40 -> 0 | R40: =+G22-Q42 -> 24473
A41: भुशी चली | B41: 0 | D41: 0 | F41: DELUX BRAN | G41: 164 | H41: 49 | I41: =G41*49/100 -> 80.36 | J41: =I41/I43*100 -> 19.384408 | K41: DELUX BRAN 49KG | P41: =O41+M41+L41 -> 0 | R41: 2051 | S41: =+Q42-R41 -> -2051
A42: क्लाशियम | B42: 0 | E42: स्टॉक | F42: SUPER FINE BRAN | G42: 0 | H42: 49 | I42: =G42*49/100 -> 0 | J42: =I42/I43*100 -> 0 | L42: =SUM(L27:L41) -> 0 | M42: =SUM(M27:M41) -> 0 | O42: =SUM(O27:O41) -> 0 | P42: =SUM(P27:Q41) -> 0
...

Sheet Sheet10

Sheet Sheet9
B3: To,
B4: SHREE SANVALIYA TRADING CO
B5: FIRST FLOOR, 16/BLOCK -B, APMC,RUPANTAR MILL
B6: COMPOUND, ANAJ MARKET ROAD, DAHOD
B7: Dahod, Gujarat,38915
B14: From ,
B15: MANISH FLOUR MILLS PVT LTD
B16: 124/125A, BARDOLI ROAD TATETHIYA
B17: KADODARA SURAT , GUJARAT -394305
B18: Mob. 8108004715

Sheet Sheet8

Sheet Sheet7
A2: DT 29.01.2026
A4: FINISH STOCK | B4: C. STOCK | C4: P. SAUDA | D4: DIFF | I4: PENDING SAUDA
A5: PRODUCT | B5: KATTA | C5: KATTA | D5: KATTA | F5: IN QTL | G5: in% | I5: PRODUCT | J5: KATTA | L5: IN QTL | M5: IN %
A6: MAIDA BAKERY | B6: 623 | C6: 673 | D6: =B6-C6 -> -50 | E6: 50 | F6: =+C6*E6/100 -> 336.5 | G6: =(F6*100)/$E$22 -> #DIV/0! | I6: MAIDA BAKERY | J6: 673 | K6: 50 | L6: =+J6*K6/100 -> 336.5 | M6: =+L6/$P$22*100 -> #DIV/0!
A7: MAIDA 30 | B7: 0 | C7: 150 | D7: =B7-C7 -> -150 | E7: 30 | F7: =+C7*E7/100 -> 45 | G7: =(F7*100)/$E$22 -> #DIV/0! | I7: MAIDA 30KG | J7: 150 | K7: 30 | L7: =+J7*K7/100 -> 45 | M7: =+L7/$P$22*100 -> #DIV/0!
A8: MAIDA LEMINATION 50 KG | B8: 309 | C8: 920 | D8: =B8-C8 -> -611 | F8: =+C8*0.5 -> 460 | G8: =(F8*100)/$E$22 -> #DIV/0! | I8: MAIDA LEMINATION 50 KG | J8: 920 | K8: 50 | L8: =+J8*K8/100 -> 460 | M8: =+L8/$P$22*100 -> #DIV/0!
A9: REFINED WHEAT FLOUR (MAIDA) 50KG | B9: 89 | C9: 0 | D9: =B9-C9 -> 89 | E9: 50 | F9: =+C9*E9/100 -> 0 | G9: =(F9*100)/$E$22 -> #DIV/0! | I9: REFINED WHEAT FLOUR (MAIDA) 50KG | J9: 0 | K9: 50 | L9: =+J9*K9/100 -> 0 | M9: =+L9/$P$22*100 -> #DIV/0!
A10: SOOJI50 | B10: 14 | C10: 210 | D10: =B10-C10 -> -196 | E10: 50 | F10: =+C10*E10/100 -> 105 | G10: =(F10*100)/$E$22 -> #DIV/0! | I10: SOOJI 50 KG | J10: 210 | K10: 50 | L10: =+J10*K10/100 -> 105 | M10: =+L10/$P$22*100 -> #DIV/0!
A11: SOOJI30 | B11: 140 | C11: 270 | D11: =B11-C11 -> -130 | E11: 30 | F11: =+C11*E11/100 -> 81 | G11: =(F11*100)/$E$22 -> #DIV/0! | I11: Sooji 30 Kgs | J11: 270 | K11: 30 | L11: =+J11*K11/100 -> 81 | M11: =+L11/$P$22*100 -> #DIV/0!
A12: RAWA 50 | B12: 292 | C12: 20 | D12: =B12-C12 -> 272 | E12: 50 | F12: =+C12*E12/100 -> 10 | G12: =(F12*100)/$E$22 -> #DIV/0! | I12: Rawa 50 kg | J12: 20 | K12: 50 | L12: =+J12*K12/100 -> 10 | M12: =+L12/$P$22*100 -> #DIV/0!
A13: RAWA 30 | B13: 111 | C13: 0 | D13: =B13-C13 -> 111 | E13: 30 | F13: =+C13*E13/100 -> 0 | G13: =(F13*100)/$E$22 -> #DIV/0! | I13: Rawa 30 Kg | J13: 0 | K13: 30 | L13: =+J13*K13/100 -> 0 | M13: =+L13/$P$22*100 -> #DIV/0!
A14: TANDORI MAIDA 50 KG | B14: 1 | C14: 0 | D14: =B14-C14 -> 1 | E14: 50 | F14: =+C14*E14/100 -> 0 | G14: =(F14*100)/$E$22 -> #DIV/0! | I14: TANDORI MAIDA 50 KG | J14: 0 | K14: 50 | L14: =+J14*K14/100 -> 0 | M14: =+L14/$P$22*100 -> #DIV/0!
A15: CA50 | B15: 0 | D15: =B15-C15 -> 0 | E15: 50 | F15: =+C15*E15/100 -> 0 | G15: =(F15*100)/$E$22 -> #DIV/0! | I15: CA50 | K15: 50 | L15: =+J15*K15/100 -> 0 | M15: =+L15/$P$22*100 -> #DIV/0!
A16: CA30 | B16: 0 | D16: =B16-C16 -> 0 | E16: 30 | F16: =+C16*E16/100 -> 0 | G16: =(F16*100)/$E$22 -> #DIV/0! | I16: CA30 | K16: 30 | L16: =+J16*K16/100 -> 0 | M16: =+L16/$P$22*100 -> #DIV/0!
A17: FINE BRAN 40 KG | B17: 0 | D17: =B17-C17 -> 0 | E17: 40 | F17: =+C17*E17/100 -> 0 | G17: =(F17*100)/$E$22 -> #DIV/0! | I17: FINE BRAN 40 KG | K17: 5 | L17: =+J17*K17/100 -> 0 | M17: =+L17/$P$22*100 -> #DIV/0!
A18: COURS BRAN | B18: 229 | C18: 200 | D18: =B18-C18 -> 29 | E18: 39 | F18: =+C18*E18/100 -> 78 | G18: =(F18*100)/$E$22 -> #DIV/0! | I18: COURS BRAN | J18: 200 | K18: 39 | L18: =+J18*K18/100 -> 78 | M18: =+L18/$P$22*100 -> #DIV/0!
A19: Bran Fine 49 KG | B19: 2167 | C19: 0 | D19: =B19-C19 -> 2167 | E19: 49 | F19: =+C19*E19/100 -> 0 | G19: =(F19*100)/$E$22 -> #DIV/0! | I19: Bran Fine 49 KG | J19: 0 | K19: 49 | L19: =+J19*K19/100 -> 0 | M19: =+L19/$P$22*100 -> #DIV/0!
A20: DELUX BRAN | B20: 1215 | C20: 0 | D20: =B20-C20 -> 1215 | E20: 49 | F20: =+C20*E20/100 -> 0 | G20: =(F20*100)/$E$22 -> #DIV/0! | I20: DELUX BRAN 49KG | J20: 0 | K20: 49 | L20: =+J20*K20/100 -> 0 | M20: =+L20/$P$22*100 -> #DIV/0!
A21: SUPER DELUX BRAN | B21: 0 | C21: 0 | D21: =B21-C21 -> 0 | E21: 49 | F21: =+C21*E21/100 -> 0 | G21: =(F21*100)/$E$22 -> #DIV/0! | I21: SUPER DELUX BRAN | J21: 0 | K21: 40 | L21: =+J21*0.4 -> 0 | M21: =+L21/$P$22*100 -> #DIV/0!
C22: 0 | D22: =B22-C22 -> 0 | J22: 0
C23: 0 | D23: =B23-C23 -> 0 | J23: 0
A24: TOTAL | B24: =SUM(B6:B21) -> 5190 | C24: =SUM(C6:C21) -> 2443 | F24: =SUM(F6:F21) -> 1115.5 | G24: =SUM(G6:G21) -> #DIV/0! | I24: TOTAL | J24: =SUM(J6:J21) -> 2443 | L24: =SUM(L6:L21) -> 1115.5 | M24: =SUM(M6:M21) -> #DIV/0!

Sheet Sheet6

Sheet Sheet5

Sheet Sheet4
B3: TODAYS PPODUCTION
B4: PRODUCT | C4: KATTA | E4: IN QTL | F4: IN %
B5: MAIDA | C5: 0 | D5: 50 | E5: =C5*50/100 -> 0 | F5: =E5/E21*100 -> 0
B6: MAIDA 30 | C6: 0 | D6: 30 | E6: =C6*30/100 -> 0 | F6: =E6/E21*100 -> 0 | K6: CHK | L6: CRN | M6: WHEAT
B7: MAIDA LEMINATION 50 KG | C7: 0 | D7: 50 | E7: =C7*50/100 -> 0 | F7: =E7/E21*100 -> 0 | J7: 16.12 | K7: 1274 | L7: 32 | M7: 649.48
B8: PARLE | C8: 0 | D8: 50 | E8: =C8*50/100 -> 0 | F8: =E8/E21*100 -> 0 | J8: 17.12 | K8: 1495 | L8: 39 | M8: 762.32
B9: SOOJI50 | C9: 0 | D9: 50 | E9: =C9*50/100 -> 0 | F9: =E9/E21*100 -> 0
B10: SOOJI30 | C10: 0 | D10: 30 | E10: =C10*30/100 -> 0 | F10: =E10/E21*100 -> 0 | J10: 20.12 | K10: 985 | L10: 25 | M10: 502.25
B11: CA50 | C11: 608 | D11: 50 | E11: =C11*50/100 -> 304 | F11: =E11/E21*100 -> 97.988654 | J11: 22.12 | K11: 880 | L11: 22 | M11: 448.48 | N11: =M11+M10 -> 950.73 | O11: 950 | P11: =N11-O11 -> 0.73
B12: RAWA 30 | C12: 0 | D12: 30 | E12: =C12*30/100 -> 0 | F12: =E12/E21*100 -> 0 | J12: 23.12 | K12: 434 | L12: 11 | M12: 221.29
B13: TM50 | C13: 0 | D13: 50 | E13: =C13*50/100 -> 0 | F13: =E13/E21*100 -> 0
B14: CA50 | C14: 0 | D14: 50 | E14: =C14*50/100 -> 0 | F14: 0 | J14: 28.12 | K14: 1285 | L14: 33 | M14: 655.37
B15: CA30 | C15: 0 | D15: 30 | E15: 0 | F15: 0 | J15: 29.12 | K15: 970 | L15: 25 | M15: 494.75
B16: Bran Fine 40 KG | C16: 0 | D16: 40 | E16: =C16*40/100 -> 0 | F16: =E16/E21*100 -> 0 | J16: 29.12
B17: COURS BRAN | C17: 16 | D17: 39 | E17: =C17*39/100 -> 6.24 | F17: =E17/E21*100 -> 2.0113461 | J17: 30.12 | K17: 1350 | L17: 35 | M17: 688.65
B18: FINE BRAN | C18: 0 | D18: 49 | E18: =C18*49/100 -> 0 | F18: =E18/E21*100 -> 0 | J18: 31.12 | K18: 970 | L18: 25 | M18: 494.75
B19: DELUX BRAN | C19: 0 | D19: 49 | E19: =C19*49/100 -> 0 | F19: =E19/E21*100 -> 0 | J19: 1.1 | K19: 866 | L19: 21 | M19: 441.19 | P19: 778 | Q19: 31 | R19: 401
B20: SUPER FINE BRAN | C20: 0 | D20: 49 | E20: =C20*49/100 -> 0 | F20: =E20/E21*100 -> 0 | O20: 23.12 | P20: 424 | Q20: 11 | R20: 221.29
B21: TOTAL | C21: =SUM(C5:C20) -> 624 | E21: =SUM(E5:E20) -> 310.24 | F21: =SUM(F5:F20) -> 100 | P21: =SUM(P19:P20) -> 1202 | Q21: =SUM(Q19:Q20) -> 42 | R21: =SUM(R19:R20) -> 622.29
K22: 608 | L22: 16 | M22: 310.24
J23: 16.12 | K23: 1274 | L23: 32 | M23: 649.48
K24: =SUM(K22:K23) -> 1882 | L24: =SUM(L22:L23) -> 48 | M24: =SUM(M22:M23) -> 959.72
P25: 699 | Q25: 24 | R25: 359
K26: 598 | L26: 15 | M26: 304.85 | O26: 28.12 | P26: 1285 | Q26: 33 | R26: 655.37
J27: 17.12 | K27: 1495 | L27: 39 | M27: 762.32 | P27: =SUM(P25:P26) -> 1984 | Q27: =SUM(Q25:Q26) -> 57 | R27: =SUM(R25:R26) -> 1014.37
K28: =SUM(K26:K27) -> 2093 | L28: =SUM(L26:L27) -> 54 | M28: =SUM(M26:M27) -> 1067.17
P29: 818 | Q29: 26 | R29: 419
O30: 29.12 | P30: 970 | Q30: 25 | R30: 494.75
K31: 825 | L31: 26 | M31: 421 | P31: =SUM(P29:P30) -> 1788 | Q31: =SUM(Q29:Q30) -> 51 | R31: =SUM(R29:R30) -> 913.75
J32: 22.12 | K32: 880 | L32: 22 | M32: 448.48
K33: =SUM(K31:K32) -> 1705 | L33: =SUM(L31:L32) -> 48 | M33: =SUM(M31:M32) -> 869.48
P34: 322 | Q34: 13 | R34: 166
O35: 31.12 | P35: 970 | Q35: 25 | R35: 494.75
P36: =SUM(P34:P35) -> 1292 | Q36: =SUM(Q34:Q35) -> 38 | R36: =SUM(R34:R35) -> 660.75

Sheet Sheet3

Sheet Sheet2
A1: SALESMAN WISE SALES REPORT | F1: SALESMAN WISE SALES REPORT
A2: LAST MONTH TILL DATE | F2: MONTH TILL DATE
A3: ITEM NAME | B3: ADITYA | C3: ADMIN | D3: KAILASH SHARMA | F3: ITEM NAME | G3: ADITYA | H3: ADMIN | I3: KAILASH SHARMA
A4: Bran Fine 49 KG | B4: 1593 | C4: 482 | D4: 65 | F4: Bran Fine 49 KG | G4: 510 | I4: 510 | K4: =(G4-B4)/B4 -> -0.67984934
A5: Bran ROUGH 39 KG-Non Branded | B5: 0 | D5: 180 | F5: DELUX BRAN 49KG | G5: 510 | I5: 510 | K5: =(G5-B6)/G5 -> -9.4117647
A6: DELUX BRAN 49KG | B6: 5310 | D6: 430 | F6: MAIDA 30KG | H6: 200 | I6: 200
A7: FINE BRAN 40 KG | B7: 0 | D7: 80 | F7: MAIDA PREMIUM 50 KG | H7: 2239 | I7: 2239
A8: MAIDA 30KG | B8: 195 | D8: 1725 | F8: Rawa 30 Kg | G8: 10 | H8: 55 | I8: 65
A9: MAIDA PREMIUM 50 KG | B9: 1005 | D9: 10547 | F9: Rawa 50 kg | H9: 177 | I9: 177
A10: POWER MESH 50 KG | B10: 25 | D10: 0 | F10: Sooji 30 Kgs | G10: 10 | H10: 120 | I10: 130
A11: Rawa 30 Kg | B11: 10 | D11: 512 | F11: SOOJI 50 KG | H11: 70 | I11: 70
A12: Rawa 50 kg | B12: 0 | D12: 927 | F12: TANDORI MAIDA 50 KG | H12: 247 | I12: 247
A13: Sooji 30 Kgs | B13: 10 | D13: 408 | F13: (MAIDA LEMINATION ) 50 KG | G13: 1216 | H13: 288 | I13: 1504
A14: SOOJI 50 KG | B14: 40 | D14: 847 | F14: Grand Total | G14: =SUM(G3:G13) -> 2256 | H14: 482 | I14: =SUM(I3:I13) -> 5652
A15: TANDORI MAIDA 50 KG | B15: 10 | D15: 793
A16: WHEAT FLOUR (MAIDA LEMINATION ) 50 KG | B16: 3736 | D16: 3993
A17: Grand Total | B17: =SUM(B4:B16) -> 11934 | C17: 482 | D17: =SUM(D4:D16) -> 20507

Sheet june 6
A3: SALES REPORT
A4: ADITYA JI
A5: PRODUCT | B5: KATTA | C5: AMOUNT | D5: kg | E5: in qtl | F5: av rate | G5: WHEAT RT | H5: DIFF | I5: KATTA
A6: MAIDA 30 | B6: 30 | C6: 28770 | D6: 30 | E6: =+B6*D6/100 -> 9 | F6: =+C6/E6 -> 3196.6667 | G6: =+'REPORT DATA SHEET'!M58 -> #DIV/0! | H6: =+F6-G6 -> #DIV/0! | I6: =+C6/B6 -> 959
A7: WHEAT FLOUR (MAIDA LEMINATION ) 50 KG | B7: 470 | C7: 747550 | D7: 50 | E7: =+B7*D7/100 -> 235 | F7: =+C7/E7 -> 3181.0638 | G7: =+'REPORT DATA SHEET'!M58 -> #DIV/0! | H7: =+F7-G7 -> #DIV/0! | I7: =+C7/B7 -> 1590.5319
A8: RAWA 50 | B8: 10 | C8: 16710 | D8: 50 | E8: =+B8*D8/100 -> 5 | F8: =+C8/E8 -> 3342 | G8: =+'REPORT DATA SHEET'!M58 -> #DIV/0! | H8: =+F8-G8 -> #DIV/0! | I8: =+C8/B8 -> 1671
A11: TOTAL | B11: =SUM(B6:B10) -> 510 | C11: =SUM(C6:C10) -> 793030 | E11: =SUM(E6:E10) -> 249 | F11: =+C11/E11 -> 3184.8594 | G11: =+G6 -> #DIV/0! | H11: =+F11-G11 -> #DIV/0!
A13: DEEPAK JI SHARMA | M13: 130
A14: PRODUCT | B14: KATTA | C14: AMOUNT | D14: kg | E14: in qtl | F14: av rate | G14: WHEAT RT | H14: DIFF | I14: KATTA | M14: 80
D15: 50 | E15: =+B15*D15/100 -> 0 | F15: =+C15/E15 -> #DIV/0! | G15: =+G11 -> #DIV/0! | H15: =+F15-G15 -> #DIV/0! | I15: =+C15/B15 -> #DIV/0! | M15: =+M13*M14 -> 10400
A21: TOTAL | B21: =SUM(B15:B19) -> 0 | C21: =SUM(C15:C19) -> 0 | D21: 0 | E21: =SUM(E15:E19) -> 0 | F21: =+C21/E21 -> #DIV/0! | G21: =+G11 -> #DIV/0! | H21: =+F21-G21 -> #DIV/0! | J21: 1321 | K21: =+B21-J21 -> -1321
A23: KAILASH JI SHARMA
A24: PRODUCT | B24: KATTA | C24: AMOUNT | D24: kg | E24: in qtl | F24: av rate | G24: WHEAT RT | H24: DIFF | I24: KATTA
A25: MAIDA 30KG | B25: 120 | C25: 117600 | D25: 30 | E25: =+B25*D25/100 -> 36 | F25: =+C25/E25 -> 3266.6667 | G25: =+G11 -> #DIV/0! | H25: =+F25-G25 -> #DIV/0! | I25: =+C25/B25 -> 980
A26: MAIDA PREMIUM 50 KG | B26: 255 | C26: 417900 | D26: 50 | E26: =+B26*D26/100 -> 127.5 | F26: =+C26/E26 -> 3277.6471 | G26: =+G25 -> #DIV/0! | H26: =+F26-G26 -> #DIV/0! | I26: =+C26/B26 -> 1638.8235
A27: Rawa 30 Kg | B27: 82 | C27: 85140 | D27: 30 | E27: =+B27*D27/100 -> 24.6 | F27: =+C27/E27 -> 3460.9756 | G27: =+G26 -> #DIV/0! | H27: =+F27-G27 -> #DIV/0! | I27: =+C27/B27 -> 1038.2927
A28: Rawa 50 kg | B28: 250 | C28: 435000 | D28: 50 | E28: =+B28*D28/100 -> 125 | F28: =+C28/E28 -> 3480 | G28: =+G27 -> #DIV/0! | H28: =+F28-G28 -> #DIV/0!
A29: Sooji 30 Kgs | B29: 12 | C29: 12600 | D29: 30 | E29: =+B29*D29/100 -> 3.6 | F29: =+C29/E29 -> 3500 | G29: =+G28 -> #DIV/0! | H29: =+F29-G29 -> #DIV/0!
A30: TANDORI MAIDA 50 KG | B30: 45 | C30: 79200 | D30: 50 | E30: =+B30*D30/100 -> 22.5 | F30: =+C30/E30 -> 3520 | G30: =+G29 -> #DIV/0! | H30: =+F30-G30 -> #DIV/0!
A32: TOTAL | B32: =SUM(B25:B31) -> 764 | C32: =SUM(C25:C31) -> 1147440 | D32: 0 | E32: =SUM(E25:E31) -> 339.2 | F32: =+C32/E32 -> 3382.783 | G32: =+G21 -> #DIV/0! | H32: =+F32-G32 -> #DIV/0! | I32: =+C32/B32 -> 1501.8848
A35: admin
A36: PRODUCT | B36: KATTA | C36: AMOUNT | D36: kg | E36: in qtl | F36: av rate | G36: WHEAT RT | H36: DIFF | I36: KATTA
D37: 49 | E37: =+B37*D37/100 -> 0 | F37: =+C37/E37 -> #DIV/0! | G37: =+G32 -> #DIV/0! | H37: =+F37-G37 -> #DIV/0! | I37: =+C37/B37 -> #DIV/0!
D38: 49 | E38: =+B38*D38/100 -> 0 | F38: =+C38/E38 -> #DIV/0! | G38: =+G37 -> #DIV/0! | H38: =+F38-G38 -> #DIV/0! | I38: =+C38/B38 -> #DIV/0!
A40: TOTAL | B40: =SUM(B37:B38) -> 0 | C40: =SUM(C37:C38) -> 0 | E40: =SUM(E37:E38) -> 0 | F40: =+C40/E40 -> #DIV/0! | G40: =+G32 -> #DIV/0! | H40: =+F40-G40 -> #DIV/0!
A44: SALES MAN | B44: katta | C44: in qtl | D44: amount | E44: AV RATE | F44: WHEAT RT | G44: DIFF | H44: katta
A45: ADITYA JI | B45: =+B11 -> 510 | C45: =+E11 -> 249 | D45: =+C11 -> 793030 | E45: =+D45/C45 -> 3184.8594 | F45: =+G40 -> #DIV/0! | G45: =+E45-F45 -> #DIV/0! | H45: =+D45/B45 -> 1554.9608
A46: KAILASH JI SHARMA | B46: =+B32 -> 764 | C46: =+E32 -> 339.2 | D46: =+C32 -> 1147440 | E46: =+D46/C46 -> 3382.783 | F46: =+F45 -> #DIV/0! | G46: =+E46-F46 -> #DIV/0! | H46: =+D46/B46 -> 1501.8848
A47: DEEPAK JI SHARMA | B47: =+B21 -> 0 | C47: =+E21 -> 0 | D47: =+C21 -> 0 | E47: =+D47/C47 -> #DIV/0! | F47: =+F46 -> #DIV/0! | G47: =+E47-F47 -> #DIV/0! | H47: =+D47/B47 -> #DIV/0!
A48: admin ji | B48: =+B40 -> 0 | C48: =+E40 -> 0 | D48: =+C40 -> 0 | E48: =+D48/C48 -> #DIV/0! | F48: =+F47 -> #DIV/0! | G48: =+E48-F48 -> #DIV/0! | H48: =+D48/B48 -> #DIV/0!
A49: TOTAL | B49: =+B45+B46+B47+B48 -> 1274 | C49: =SUM(C45:C48) -> 588.2 | D49: =SUM(D45:D48) -> 1940470 | E49: =+D49/C49 -> 3298.9969 | F49: =+F45 -> #DIV/0! | G49: =+E49-F49 -> #DIV/0!
B51: =+'REPORT DATA SHEET'!G22 -> 24473 | C51: =+'REPORT DATA SHEET'!I22 -> 11721.29 | D51: =+'REPORT DATA SHEET'!K22 -> 0
B52: =+B49-B51 -> -23199 | C52: =+C49-C51 -> -11133.09 | D52: =+D49-D51 -> 1940470 | G52: 27

Sheet PARTAL REPORT 
B1: DATE :- 25-06-26 | U1: FINISH STOCK | Z1: SALES PENDING SOUDA | AC1: diff
B2: PRODUCTS | D2: YIELD IN % | E2: RATE BAG | F2: RATE KG | G2: AVG RATE | U2: PRODUCT | V2: KATTA | X2: IN QTL | Z2: KATTA | AB2: IN QTL
B3: MAIDA -I ( 50 KG ) | F3: =E3/50 -> 0 | G3: =D3*F3 -> 0 | U3: MAIDA PREMIUM 50 KG | V3: 2258 | W3: 50 | X3: =V3*0.5 -> 1129 | Z3: =+VLOOKUP(U3,#REF!,2,0) -> #REF! | AA3: 50 | AB3: =+Z3*AA3/100 -> #REF! | AC3: =+V3-Z3 -> #REF!
B4: MAIDA LEMINATION ) 50 KG | F4: =E4/50 -> 0 | G4: =D4*F4 -> 0
B5: REFINED WHEAT FLOUR MAIDA | F5: =E5/50 -> 0 | G5: =D5*F5 -> 0 | U5: MAIDA 30 | V5: 166 | W5: 30 | X5: =+V5*W5/100 -> 49.8 | Z5: 0 | AA5: 30 | AB5: =+Z5*AA5/100 -> 0 | AC5: =+V5-Z5 -> 166
B6: SOOJI ( 50 KG ) | F6: =E6/50 -> 0 | G6: =D6*F6 -> 0 | U6: WHEAT FLOUR (MAIDA LEMINATION ) 50 KG | V6: 5282 | X6: =+V6*0.5 -> 2641 | Z6: =+VLOOKUP(U6,#REF!,2,0) -> #REF! | AB6: =+Z6*0.5 -> #REF! | AC6: =+V6-Z6 -> #REF!
B7: RAWA (50 KG ) | F7: =E7/50 -> 0 | G7: =D7*F7 -> 0 | K7: 46023 | U7: REFINED WHEAT FLOUR (MAIDA) 50KG | W7: 50 | X7: =+V7*W7/100 -> 0 | Z7: =+VLOOKUP(U7,#REF!,2,0) -> #REF! | AA7: 50 | AB7: =+Z7*AA7/100 -> #REF! | AC7: =+V7-Z7 -> #REF!
B8: T-ATTA (50 KG ) | F8: =E8/50 -> 0 | G8: =D8*F8 -> 0 | K8: ELECTRIC BILL | L8: 1238703 | U8: SOOJI 50 KG | V8: 378 | W8: 50 | X8: =+V8*W8/100 -> 189 | Z8: =+VLOOKUP(U8,#REF!,2,0) -> #REF! | AA8: 50 | AB8: =+Z8*AA8/100 -> #REF! | AC8: =+V8-Z8 -> #REF!
B9: R-BRAN ( 39 KG ) | F9: =E9/39 -> 0 | G9: =D9*F9 -> 0 | K9: SALARY | L9: 2200000 | U9: Sooji 30 Kgs | V9: 356 | W9: 30 | X9: =+V9*W9/100 -> 106.8 | Z9: =+VLOOKUP(U9,#REF!,2,0) -> #REF! | AA9: 30 | AB9: =+Z9*AA9/100 -> #REF! | AC9: =+V9-Z9 -> #REF!
B10: FINE BRAN ( 49 KG ) | F10: =E10/49 -> 0 | G10: =D10*F10 -> 0 | K10: PP BAG | L10: 1100000 | S10: 110 | U10: Rawa 50 kg | V10: 845 | W10: 50 | X10: =+V10*W10/100 -> 422.5 | Z10: =+VLOOKUP(U10,#REF!,2,0) -> #REF! | AA10: 50 | AB10: =+Z10*AA10/100 -> #REF! | AC10: =+V10-Z10 -> #REF!
B11: S. DELUXE BRAN ( 49 KG ) | F11: =E11/49 -> 0 | G11: =D11*F11 -> 0 | K11: CC INT.. | L11: 1000000 | S11: =+S10*8 -> 880 | U11: Rawa 30 Kg | V11: 285 | W11: 30 | X11: =+V11*W11/100 -> 85.5 | Z11: =+VLOOKUP(U11,#REF!,2,0) -> #REF! | AA11: 30 | AB11: =+Z11*AA11/100 -> #REF! | AC11: =+V11-Z11 -> #REF!
B12: DELUXE BRAN ( 49 KG ) | F12: =E12/49 -> 0 | G12: =D12*F12 -> 0 | K12: REPAIR & MAINTANANCE | L12: 590000 | U12: TANDORI MAIDA 50 KG | V12: 673 | W12: 50 | X12: =+V12*W12/100 -> 336.5 | Z12: =+VLOOKUP(U12,#REF!,2,0) -> #REF! | AA12: 50 | AB12: =+Z12*AA12/100 -> #REF! | AC12: =+V12-Z12 -> #REF!
D13: =SUM(D3:D12) -> 0 | E13: REALIZATION VALUE | G13: =SUM(G3:G12) -> 0 | K13: Staff Welfare A/c | L13: 230000 | U13: CA50 | V13: 0 | W13: 50 | X13: =+V13*W13/100 -> 0 | Z13: 0 | AA13: 50 | AB13: =+Z13*AA13/100 -> 0 | AC13: =+V13-Z13 -> 0
B14: NOTE :- WHEAT & ATTA MAIDA AVG | E14: WHEAT NET AVG RATE | G14: ='REPORT DATA SHEET'!P58 -> #DIV/0! | K14: TRAVELLING EXPENSES | L14: 150000 | U14: CA30 | V14: 0 | W14: 30 | X14: =+V14*W14/100 -> 0 | Z14: 0 | AA14: 30 | AB14: =+Z14*AA14/100 -> 0 | AC14: =+V14-Z14 -> 0
B15: RATE TILL DATE | E15: DIFFRENCE | G15: =+G13-G14 -> #DIV/0! | K15: PEST CONTROL | L15: 27140 | U15: CA05 | V15: 0 | W15: 5 | X15: =+V15*W15/100 -> 0 | Z15: 0 | AA15: 5 | AB15: =+Z15*AA15/100 -> 0 | AC15: =+V15-Z15 -> 0
E16: GRD EXP. | G16: 0 | K16: DIRECTOR REMUNARATION | L16: 400000 | U16: COURS BRAN | V16: 218 | W16: 39 | X16: =+V16*W16/100 -> 85.02 | Z16: 0 | AA16: 39 | AB16: =+Z16*AA16/100 -> 0 | AC16: =+V16-Z16 -> 218
E17: MOISTURE @ 3% | G17: =+G14*0.03 -> #DIV/0! | K17: Building Repaire & Maintance | L17: 300000 | U17: Bran Fine 49 KG | V17: 2840 | W17: 49 | X17: =+V17*W17/100 -> 1391.6 | Z17: =+VLOOKUP(U17,#REF!,2,0) -> #REF! | AA17: 49 | AB17: =+Z17*AA17/100 -> #REF! | AC17: =+V17-Z17 -> #REF!
E18: FINAL | G18: =+G15+G17-G16 -> #DIV/0! | K18: Printing & Stationery Exp | L18: 15000 | R18: 117 | S18: =+H18*R18 -> 0 | U18: DELUX BRAN 49KG | V18: 5785 | W18: 49 | X18: =+V18*W18/100 -> 2834.65 | Z18: =+VLOOKUP(U18,#REF!,2,0) -> #REF! | AA18: 49 | AB18: =+Z18*AA18/100 -> #REF! | AC18: =+V18-Z18 -> #REF!
K19: Transport Exp. A/c | L19: 8000 | S19: =+S18/7 -> 0 | U19: SUPER DELUX BRAN | V19: 345 | W19: 49 | X19: =+V19*W19/100 -> 169.05 | Z19: 0 | AA19: 49 | AB19: =+Z19*AA19/100 -> 0
K20: Interest Paid (Expenses) BMW | L20: 70000
K21: Wherehouse Rent | L21: 400000 | R21: 2000
K22: Rent Pune | L22: 155000 | U22: TOTAL | V22: =SUM(V3:V19) -> 19431 | X22: =SUM(X3:X19) -> 9440.42 | Z22: =SUM(Z3:Z19) -> #REF! | AB22: =SUM(AB3:AB19) -> #REF! | AC22: =SUM(AC3:AC21) -> #REF!
B23: DATE :- 05.10.2025 | K23: Bardana Repaire | L23: 70000
B24: PRODUCTS | D24: YIELD IN % | E24: RATE BAG | F24: RATE KG | G24: AVG RATE | K24: MAIDA TRANSPORT | L24: 102000
B25: MAIDA -I ( 50 KG ) | D25: 22.1 | E25: =+'AUG TILL DATE '!T7 -> 1644.4511 | F25: =E25/50 -> 32.889022 | G25: =D25*F25 -> 726.84739 | K25: Cash discount | L25: 580000
B26: MAIDA -II ( 50 KG ) | D26: 33.7 | E26: =+'AUG TILL DATE '!T9 -> 1526.8303 | F26: =E26/50 -> 30.536606 | G26: =D26*F26 -> 1029.0836 | K26: TOTAL | L26: =SUM(L8:L25) -> 8635843
B27: SOOJI ( 50 KG ) | D27: 5.3 | E27: =+'AUG TILL DATE '!AB10 -> #ERROR! | F27: =E27/50 -> #ERROR! | G27: =D27*F27 -> #ERROR!
B28: RAWA (50 KG ) | D28: 5.7 | E28: =+'AUG TILL DATE '!T13 -> 1716.0409 | F28: =E28/50 -> 34.320818 | G28: =D28*F28 -> 195.62866
B29: T-ATTA (50 KG ) | D29: 3.1 | E29: =+'AUG TILL DATE '!T15 -> 1750.0756 | F29: =E29/50 -> 35.001513 | G29: =D29*F29 -> 108.50469
B30: R-BRAN ( 39 KG ) | D30: 0 | E30: =+'AUG TILL DATE '!T19 -> 850 | F30: =E30/39 -> 21.794872 | G30: =D30*F30 -> 0
B31: FINE BRAN ( 49 KG ) | D31: 5 | E31: =+'AUG TILL DATE '!T20 -> 777.0252 | F31: =E31/49 -> 15.857657 | G31: =D31*F31 -> 79.288286
B32: S. DELUXE BRAN ( 49 KG ) | D32: 0 | E32: 1300 | F32: =E32/49 -> 26.530612 | G32: =D32*F32 -> 0
B33: DELUXE BRAN ( 49 KG ) | D33: 25.1 | E33: =+'AUG TILL DATE '!T21 -> 1050.6328 | F33: =E33/49 -> 21.441485 | G33: =D33*F33 -> 538.18127
D34: =SUM(D25:D33) -> 100 | E34: REALIZATION VALUE | G34: =SUM(G25:G33) -> #ERROR!
C35: wheat rate | D35: 2875 | E35: WHEAT RATE LESS 4% | G35: =+'AUG TILL DATE '!P35 -> #DIV/0!
C36: 0.04 | D36: =+D35*4/100 -> 115 | E36: DIFFRENCE | G36: =+G34-G35 -> #ERROR!
E37: GRD EXP. | G37: 250
E38: MOISTURE @ 3% | G38: =+G35*0.03 -> #DIV/0!
E39: FINAL | G39: =+G36+G38-G37 -> #ERROR!

Sheet AUG TILL DATE 
A3: SALES REPORT 17.10.2025
A4: ADITYA JI
A5: PRODUCT | B5: KATTA | C5: AMOUNT | D5: kg | E5: in qtl | F5: av rate | G5: WHEAT RT | H5: DIFF | I5: KATTA RATE | M5: SALES REPORT
A6: Bran Fine 49 KG | B6: 4001 | C6: 3161760 | D6: 49 | E6: =+B6*D6/100 -> 1960.49 | F6: =+C6/E6 -> 1612.7397 | G6: =+'REPORT DATA SHEET'!O58 -> #DIV/0! | H6: =+F6-G6 -> #DIV/0! | I6: =+C6/B6 -> 790.24244 | M6: PRODUCT | N6: KATTA | P6: IN QTL | Q6: IN % | R6: AMOUNT | S6: RATE | T6: katta rate
A7: DELUX BRAN 49KG | B7: 6510 | C7: 6863170 | D7: 49 | E7: =+B7*D7/100 -> 3189.9 | F7: =+C7/E7 -> 2151.5314 | G7: =+G6 -> #DIV/0! | H7: =+F7-G7 -> #DIV/0! | I7: =+C7/B7 -> 1054.2504 | M7: MAIDA PREMIUM 50 KG | N7: 9705 | O7: 50 | P7: =+N7*O7/100 -> 4852.5 | Q7: =(P7*100)/$P$24 -> 29.16236 | R7: 15959398 | S7: =+R7/P7 -> 3288.9022 | T7: =+S7/2 -> 1644.4511 | U7: 2845 | V7: =+S7-U7 -> 443.90222
A8: MAIDA 30KG | B8: 377 | C8: 367198 | D8: 30 | E8: =+B8*D8/100 -> 113.1 | F8: =+C8/E8 -> 3246.6667 | G8: =+G7 -> #DIV/0! | H8: =+F8-G8 -> #DIV/0! | I8: =+C8/B8 -> 974 | M8: MAIDA 30KG | N8: 1457 | O8: 30 | P8: =+N8*O8/100 -> 437.1 | Q8: =(P8*100)/$P$24 -> 2.626866 | R8: 1430018 | S8: =+R8/P8 -> 3271.6038 | T8: =+S8/100*30 -> 981.48113 | U8: 2845 | V8: =+S8-U8 -> 426.60375
A9: MAIDA PREMIUM 50 KG | B9: 3626 | C9: 5899160 | D9: 50 | E9: =+B9*D9/100 -> 1813 | F9: =+C9/E9 -> 3253.8114 | G9: =+G8 -> #DIV/0! | H9: =+F9-G9 -> #DIV/0! | I9: =+C9/B9 -> 1626.9057 | M9: REFINED WHEAT FLOUR (MAIDA) 50KG | N9: 3565 | O9: 50 | P9: =+N9*O9/100 -> 1782.5 | Q9: =(P9*100)/$P$24 -> 10.712397 | R9: 5443150 | S9: =+R9/P9 -> 3053.6606 | T9: =+S9/2 -> 1526.8303 | U9: 2845 | V9: =+S9-U9 -> 208.66059
A10: Rawa 30 Kg | B10: 10 | C10: 10100 | D10: 30 | E10: =+B10*D10/100 -> 3 | F10: =+C10/E10 -> 3366.6667 | G10: =+G9 -> #DIV/0! | H10: =+F10-G10 -> #DIV/0! | I10: =+C10/B10 -> 1010 | M10: WHEAT FLOUR (MAIDA LEMINATION ) 50 KG | N10: 1184 | O10: 50 | P10: =+N10*O10/100 -> 592 | Q10: =(P10*100)/$P$24 -> 3.5577778 | R10: 1933395 | S10: =+R10/P10 -> 3265.8699 | T10: =+S10/2 -> 1632.935 | U10: SOOJI 50 KG | V10: =+VLOOKUP(U10,[1]Sheet3!$A$4:$B$14,2,0) -> #ERROR! | W10: 50 | X10: =+V10*W10/100 -> #ERROR! | Y10: =(X10*100)/$P$24 -> #ERROR! | Z10: =+VLOOKUP(U10,[1]Sheet3!$A$4:$C$14,3,0) -> #ERROR! | AA10: =+Z10/X10 -> #ERROR! | AB10: =+AA10/2 -> #ERROR! | AC10: 2845 | AD10: =+AA10-AC10 -> #ERROR!
A11: Rawa 50 kg | B11: 170 | C11: 285450 | D11: 50 | E11: =+B11*D11/100 -> 85 | F11: =+C11/E11 -> 3358.2353 | G11: =+G10 -> #DIV/0! | H11: =+F11-G11 -> #DIV/0! | I11: =+C11/B11 -> 1679.1176 | M11: SOOJI 50 KG | N11: 867 | O11: 50 | P11: =+N11*O11/100 -> 433.5 | Q11: =(P11*100)/$P$24 -> 2.6052309 | R11: 1503920 | V11: =+S12-U12 -> 628.34895
A12: REFINED WHEAT FLOUR (MAIDA) 50KG | B12: 3025 | C12: 4599500 | D12: 50 | E12: =+B12*D12/100 -> 1512.5 | F12: =+C12/E12 -> 3040.9917 | G12: =+G11 -> #DIV/0! | H12: =+F12-G12 -> #DIV/0! | I12: =+C12/B12 -> 1520.4959 | M12: Sooji 30 Kgs | N12: 1281 | O12: 30 | P12: =+N12*O12/100 -> 384.3 | Q12: =(P12*100)/$P$24 -> 2.3095507 | R12: 1334808 | S12: =+R12/P12 -> 3473.3489 | T12: =+S12/100*30 -> 1042.0047 | U12: 2845 | V12: =+S13-U13 -> 587.08178
A13: Sooji 30 Kgs | B13: 10 | C13: 10100 | D13: 30 | E13: =+B13*D13/100 -> 3 | F13: =+C13/E13 -> 3366.6667 | G13: =+G12 -> #DIV/0! | H13: =+F13-G13 -> #DIV/0! | I13: =+C13/B13 -> 1010 | M13: Rawa 50 kg | N13: 1712 | O13: 50 | P13: =+N13*O13/100 -> 856 | Q13: =(P13*100)/$P$24 -> 5.1443544 | R13: 2937862 | S13: =+R13/P13 -> 3432.0818 | T13: =+S13/2 -> 1716.0409 | U13: 2845 | V13: =+S14-U18 -> 635.39216
A14: SOOJI 50 KG | B14: 105 | C14: 177400 | D14: 50 | E14: =+B14*D14/100 -> 52.5 | F14: =+C14/E14 -> 3379.0476 | G14: =+G13 -> #DIV/0! | H14: =+F14-G14 -> #DIV/0! | I14: =+C14/B14 -> 1689.5238 | M14: Rawa 30 Kg | N14: 425 | O14: 30 | P14: =+N14*O14/100 -> 127.5 | Q14: =(P14*100)/$P$24 -> 0.76624438 | R14: 443750 | S14: =+R14/P14 -> 3480.3922 | T14: =+S14/100*30 -> 1044.1176
A15: TANDORI MAIDA 50 KG | B15: 70 | C15: 117850 | D15: 50 | E15: =+B15*D15/100 -> 35 | F15: =+C15/E15 -> 3367.1429 | G15: =+G14 -> #DIV/0! | H15: =+F15-G15 -> #DIV/0! | I15: =+C15/B15 -> 1683.5714 | M15: TANDORI MAIDA 50 KG | N15: 1190 | O15: 50 | P15: =+N15*O15/100 -> 595 | Q15: =(P15*100)/$P$24 -> 3.5758071 | R15: 2082590 | S15: =+R15/P15 -> 3500.1513 | T15: =+S15/2 -> 1750.0756
A16: WHEAT FLOUR (MAIDA LEMINATION ) 50 KG | B16: 469 | C16: 749395 | D16: 50 | E16: =+B16*D16/100 -> 234.5 | F16: =+C16/E16 -> 3195.7143 | G16: =+G15 -> #DIV/0! | H16: =+F16-G16 -> #DIV/0! | I16: =+C16/B16 -> 1597.8571 | M16: CA50 | N16: 0 | O16: 50 | P16: =+N16*O16/100 -> 0 | Q16: =(P16*100)/$P$24 -> 0 | R16: 0 | S16: 0
M17: CA30 | N17: 0 | O17: 30 | P17: =+N17*O17/100 -> 0 | Q17: =(P17*100)/$P$24 -> 0 | R17: 0 | S17: 0
E18: =+B18*D18/100 -> 0 | M18: CA05 | N18: 0 | O18: 5 | P18: =+N18*O18/100 -> 0 | Q18: =(P18*100)/$P$24 -> 0 | R18: 0 | S18: 0 | U18: 2845 | V18: =+S15-U19 -> 655.15126
M19: Bran ROUGH 39 KG-Non Branded | N19: 15 | O19: 39 | P19: =+N19*0.39 -> 5.85 | Q19: =(P19*100)/$P$24 -> 0.035157095 | R19: 12750 | S19: =+R19/P19 -> 2179.4872 | T19: =+S19/100*39 -> 850 | U19: 2845 | V19: =+S16-U20 -> 0
A20: TOTAL | B20: =SUM(B6:B19) -> 18373 | C20: =SUM(C6:C18) -> 22241083 | E20: =SUM(E6:E19) -> 9001.99 | F20: =+C20/E20 -> 2470.6851 | G20: =+G6 -> #DIV/0! | H20: =+F20-G20 -> #DIV/0! | I20: =+C20/B20 -> 1210.5308 | M20: Bran Fine 49 KG | N20: 4881 | O20: 49 | P20: =+N20*O20/100 -> 2391.69 | Q20: =(P20*100)/$P$24 -> 14.373483 | R20: 3792660 | S20: =+R20/P20 -> 1585.7657 | T20: =+S20/100*49 -> 777.0252 | U20: 0 | V20: =+S17-U21 -> 0
M21: DELUX BRAN 49KG | N21: 8534 | O21: 49 | P21: =+N21*O21/100 -> 4181.66 | Q21: =(P21*100)/$P$24 -> 25.130772 | R21: 8966100 | S21: =+R21/P21 -> 2144.1485 | T21: =+S21/100*49 -> 1050.6328 | U21: 0 | V21: =+S18-U22 -> 0
M22: SUPER DELUX BRAN | N22: 0 | O22: 49 | P22: =+N22*O22/100 -> 0 | Q22: =(P22*100)/$P$24 -> 0 | R22: 0 | S22: 0 | U22: 0 | V22: =+S19-U23 -> 2179.4872
A23: KAILASH JI SHARMA | R23: 0 | U23: 0 | V23: =+S20-U24 -> -1259.2343
A24: PRODUCT | B24: KATTA | C24: AMOUNT | D24: kg | E24: in qtl | F24: av rate | G24: WHEAT RT | H24: DIFF | I24: KATTA RATE | M24: TOTAL | N24: =SUM(N7:N23) -> 34816 | P24: =SUM(P7:P22) -> 16639.6 | Q24: =SUM(Q6:Q22) -> 100 | R24: =SUM(R7:R22) -> 45840401 | S24: =+R24/P24 -> 2754.898 | U24: 2845 | V24: =+S21-U25 -> -700.8515
A25: Bran Fine 49 KG | B25: 530 | C25: 373650 | D25: 49 | E25: =+B25*D25/100 -> 259.7 | F25: =+C25/E25 -> 1438.7755 | G25: =+G20 -> #DIV/0! | H25: =+F25-G25 -> #DIV/0! | I25: =+C25/B25 -> 705 | N25: 0 | P25: =+R24/P24 -> 2754.898 | R25: 0 | U25: 2845
A26: Bran ROUGH 39 KG-Non Branded | B26: 15 | C26: 12750 | D26: 39 | E26: =+B26*D26/100 -> 5.85 | F26: =+C26/E26 -> 2179.4872 | G26: =+G25 -> #DIV/0! | H26: =+F26-G26 -> #DIV/0! | I26: =+C26/B26 -> 850 | N26: 0 | S26: diff
A27: DELUX BRAN 49KG | B27: 104 | C27: 114430 | D27: 49 | E27: =+B27*D27/100 -> 50.96 | F27: =+C27/E27 -> 2245.4867 | G27: =+G26 -> #DIV/0! | H27: =+F27-G27 -> #DIV/0! | I27: =+C27/B27 -> 1100.2885 | M27: MAIDA | N27: =+P7+P8+P9+P10+P11+P12+P13+P14+P15 -> 10060.4 | O27: =+R7+R8+R9+R10+R11+R12+R13+R14+R15 -> 33068891 | P27: =+O27/N27 -> 3287.0354 | V27: =SUM(V7:V26) -> #ERROR!
A28: MAIDA 30KG | B28: 1080 | C28: 1062820 | D28: 30 | E28: =+B28*D28/100 -> 324 | F28: =+C28/E28 -> 3280.3086 | G28: =+G27 -> #DIV/0! | H28: =+F28-G28 -> #DIV/0! | I28: =+C28/B28 -> 984.09259 | M28: ROUGH BRAN | N28: =+P19 -> 5.85 | O28: =+R19 -> 12750 | P28: =+O28/N28 -> 2179.4872
A29: MAIDA PREMIUM 50 KG | B29: 6079 | C29: 10060238 | D29: 50 | E29: =+B29*D29/100 -> 3039.5 | F29: =+C29/E29 -> 3309.8332 | G29: =+G28 -> #DIV/0! | H29: =+F29-G29 -> #DIV/0! | I29: =+C29/B29 -> 1654.9166 | M29: FINE BRAN | N29: =+P20 -> 2391.69 | O29: =+R20 -> 3792660 | P29: =+O29/N29 -> 1585.7657
A30: Rawa 30 Kg | B30: 415 | C30: 433650 | D30: 30 | E30: =+B30*D30/100 -> 124.5 | F30: =+C30/E30 -> 3483.1325 | G30: =+G29 -> #DIV/0! | H30: =+F30-G30 -> #DIV/0! | I30: =+C30/B30 -> 1044.9398 | M30: DELUX BRAN 49KG | N30: =+P21 -> 4181.66 | O30: =+R21 -> 8966100 | P30: =+O30/N30 -> 2144.1485
A31: Rawa 50 kg | B31: 1542 | C31: 2652412 | D31: 50 | E31: =+B31*D31/100 -> 771 | F31: =+C31/E31 -> 3440.2231 | G31: =+G30 -> #DIV/0! | H31: =+F31-G31 -> #DIV/0! | I31: =+C31/B31 -> 1720.1115
A32: REFINED WHEAT FLOUR (MAIDA) 50KG | B32: 540 | C32: 843650 | D32: 50 | E32: =+B32*D32/100 -> 270 | F32: =+C32/E32 -> 3124.6296 | G32: =+G31 -> #DIV/0! | H32: =+F32-G32 -> #DIV/0! | I32: =+C32/B32 -> 1562.3148 | M32: TOTAL | N32: =+N27+N28+N29+N30 -> 16639.6 | O32: =+O27+O28+O29+O30 -> 45840401 | P32: =+O32/N32 -> 2754.898
A33: Sooji 30 Kgs | B33: 1271 | C33: 1324708 | D33: 30 | E33: =+B33*D33/100 -> 381.3 | F33: =+C33/E33 -> 3474.1883 | G33: =+G32 -> #DIV/0! | H33: =+F33-G33 -> #DIV/0! | I33: =+C33/B33 -> 1042.2565
A34: SOOJI 50 KG | B34: 762 | C34: 1326520 | D34: 50 | E34: =+B34*D34/100 -> 381 | F34: =+C34/E34 -> 3481.6798 | G34: =+G33 -> #DIV/0! | H34: =+F34-G34 -> #DIV/0! | I34: =+C34/B34 -> 1740.8399
A35: TANDORI MAIDA 50 KG | B35: 1120 | C35: 1964740 | D35: 50 | E35: =+B35*D35/100 -> 560 | F35: =+C35/E35 -> 3508.4643 | G35: =+G34 -> #DIV/0! | H35: =+F35-G35 -> #DIV/0! | I35: =+C35/B35 -> 1754.2321 | M35: WHEAT RATE | P35: =+G38 -> #DIV/0!
A36: WHEAT FLOUR (MAIDA LEMINATION ) 50 KG | B36: 715 | C36: 1184000 | D36: 50 | E36: =+B36*D36/100 -> 357.5 | F36: =+C36/E36 -> 3311.8881 | G36: =+G35 -> #DIV/0! | H36: =+F36-G36 -> #DIV/0! | I36: =+C36/B36 -> 1655.9441
M37: diff | P37: =+P32-P35 -> #DIV/0!
A38: TOTAL | B38: =SUM(B25:B36) -> 14173 | C38: =SUM(C25:C36) -> 21353568 | D38: 0 | E38: =SUM(E25:E36) -> 6525.31 | F38: =+C38/E38 -> 3272.422 | G38: =+G35 -> #DIV/0! | H38: =+F38-G38 -> #DIV/0! | I38: =+C38/B38 -> 1506.6371
A41: admin
A42: PRODUCT | B42: KATTA | C42: AMOUNT | D42: kg | E42: in qtl | F42: av rate | G42: WHEAT RT | H42: DIFF | I42: KATTA RATE
A43: Bran Fine 49 KG | B43: 350 | C43: 257250 | D43: 49 | E43: =+B43*D43/100 -> 171.5 | F43: =+C43/E43 -> 1500 | G43: =+G38 -> #DIV/0! | H43: =+F43-G43 -> #DIV/0! | I43: =+C43/B43 -> 735
A44: DELUX BRAN 49KG | B44: 1920 | C44: 1988500 | D44: 49 | E44: =+B44*D44/100 -> 940.8 | F44: =+C44/E44 -> 2113.6267 | G44: =+G43 -> #DIV/0! | H44: =+F44-G44 -> #DIV/0! | I44: =+C44/B44 -> 1035.6771
...

Sheet Sheet1
B1: 42583 | C1: =+B1+1 -> 42584 | D1: =+C1+1 -> 42585 | E1: =+D1+1 -> 42586 | F1: =+E1+1 -> 42587 | G1: =+F1+1 -> 42588 | H1: =+G1+1 -> 42589 | I1: =+H1+1 -> 42590 | J1: =+I1+1 -> 42591 | ... AF1: =+AE1+1 -> 42613 | AG1: monthaly %
D2: unit consum
A3: 2510000 | B3: 2510133 | C3: 2510805 | D3: 2510905 | E3: 2511750 | F3: 2512155 | G3: 2512511 | H3: 2512658 | I3: 2512758 | J3: 2512856 | K3: 2512900 | L3: 2513210 | M3: 2513310 | N3: 2514092 | O3: 0 | P3: 2515843 | Q3: 0 | R3: 2517228 | S3: 0 | T3: 0 | U3: 0 | V3: 0 | W3: 0 | X3: 0 | Y3: 0 | Z3: 0 | AA3: 0 | AB3: 0 | AC3: 0 | AD3: 0 | AE3: 0 | AF3: 0
A5: comsum kw | B5: =+B3-A3 -> 133 | C5: =C3-B3 -> 672 | D5: 0 | E5: =E3-D3 -> 845 | F5: =F3-E3 -> 405 | G5: =G3-F3 -> 356 | H5: =H3-G3 -> 147 | I5: 0 | J5: =J3-I3 -> 98 | K5: =K3-J3 -> 44 | L5: =L3-K3 -> 310 | M5: =M3-L3 -> 100 | N5: =N3-M3 -> 782 | O5: 0 | P5: =P3-O3 -> 2515843 | Q5: =Q3-P3 -> -2515843 | R5: =R3-Q3 -> 2517228 | S5: 0 | T5: 0 | U5: =U3-T3 -> 0 | V5: 0 | W5: =W3-V3 -> 0 | X5: =X3-W3 -> 0 | Y5: =Y3-X3 -> 0 | Z5: =Z3-Y3 -> 0 | AA5: =AA3-Z3 -> 0 | AB5: =AB3-AA3 -> 0 | AC5: =AC3-AB3 -> 0 | AD5: 0 | AE5: =AE3-AD3 -> 0 | AF5: =AF3-AE3 -> 0
A6: unit | B6: =B5*16 -> 2128 | C6: =C5*16 -> 10752 | D6: =D5*16 -> 0 | E6: =E5*16 -> 13520 | F6: =F5*16 -> 6480 | G6: =G5*16 -> 5696 | H6: =H5*16 -> 2352 | I6: =I5*16 -> 0 | ... R6: =R5*16 -> 40275648 | V6: =V5*16 -> 0 | W6: =W5*16 -> 0 | X6: =X5*16 -> 0 | Y6: =Y5*16 -> 0 | Z6: =Z5*16 -> 0 | AA6: =AA5*16 -> 0 | AB6: =AB5*16 -> 0 | AC6: =AC5*16 -> 0 | ... AF6: =AF5*16 -> 0 | AG6: =SUM(B6:AF6) -> 40337920
A7: grinding | B7: 835.6 | C7: 1383.3 | D7: 1912.2 | E7: 329.67 | F7: 866.73 | G7: 740.84 | H7: 250.55 | I7: 250.55 | J7: 250.55 | K7: 250.55 | L7: 250.55 | M7: 605.55 | N7: 1776.95 | O7: 0 | P7: 2232.68 | Q7: 0 | R7: 1573.26 | S7: 0 | T7: 0 | U7: 0 | V7: 0 | W7: 0 | X7: 0 | Y7: 0 | Z7: 0 | AA7: 0 | AB7: 0 | AC7: 0 | AD7: 0 | AE7: 0 | AF7: 0 | AG7: =SUM(B7:AF7) -> 13509.53
A8: per bag consume | B8: =B6/B7 -> 2.546673 | C8: =C6/C7 -> 7.7727174 | D8: =D6/D7 -> 0 | E8: =E6/E7 -> 41.010708 | F8: =F6/F7 -> 7.4763767 | G8: =G6/G7 -> 7.6885697 | H8: =H6/H7 -> 9.3873478 | I8: =I6/I7 -> 0 | ... AG8: =AG6/AG7 -> 2985.8863
A10: PER DAY AMOUNT | B10: =+B7*8.33 -> 6960.548 | C10: =+C6*C8 -> 83572.258 | D10: =+D6*D8 -> 0 | E10: =+E6*E8 -> 554464.77 | F10: =+F6*F8 -> 48446.921 | G10: =+G6*G8 -> 43794.093 | H10: =+H6*H8 -> 22079.042 | I10: =+I6*I8 -> 0 | J10: =+J6*J8 -> 9812.9076 | ... AF10: =+AF6*AF8 -> #DIV/0!
A11: stop time | B11: 24 | C11: 15.15 | D11: 16.05 | E11: 0 | F11: 0 | G11: 15.1 | H11: 0 | I11: 12 | J11: 13.4 | K11: 14.3 | L11: 6.3 | M11: 1.3 | N11: 0 | O11: 0 | P11: 0 | Q11: 0 | R11: 0 | S11: 0 | T11: 0 | U11: 0 | V11: 0 | W11: 0 | X11: 0 | Y11: 0 | Z11: 0 | AA11: 0 | AB11: 0 | AC11: 0 | AD11: 0 | AE11: 0 | AF11: 0 | AG11: =SUM(B11:AF11) -> 117.6
A12: running | B12: 0 | C12: 8.45 | D12: 7.55 | E12: 0 | F12: 0 | G12: 8.5 | H12: 0 | I12: 12 | J12: 10.2 | K12: 9.3 | L12: 17.3 | M12: 22.3 | N12: 0 | O12: 0 | P12: 0 | Q12: 0 | R12: 0 | S12: 0 | T12: 0 | U12: 0 | V12: 0 | W12: 0 | X12: 0 | Y12: 0 | Z12: 0 | AA12: 0 | AB12: 0 | AC12: 0 | AD12: 0 | AE12: 0 | AF12: 0 | AG12: =SUM(B12:AF12) -> 95.6
B13: =+B11+B12 -> 24 | C13: =+C11+C12 -> 23.6 | D13: =+D11+D12 -> 23.6 | E13: =+E11+E12 -> 0 | F13: =+F11+F12 -> 0 | G13: =+G11+G12 -> 23.6 | H13: =+H11+H12 -> 0 | I13: =+I11+I12 -> 24 | ... AD13: =+AD11+AD12 -> 0 | AF13: =+AF11+AF12 -> 0
I16: 892
I17: 197
I18: 36
I19: 82
I20: 139
C22: SALE TODATE | D22: PURCHASE TODATE | E22: Rate Diff
B23: QTL | C23: 45389.65 | D23: =56659.789-2162 -> 54497.789
B24: AMOUNT | C24: 1.4149627e+08 | D24: =155897070-1005287 -> 154891783
B25: RATE | C25: =C24/C23 -> 3117.3685 | D25: =D24/D23 -> 2842.1664 | E25: =C25-D25 -> 275.20214

Sheet GRINDING
A3: DATE | B3: GRINDING
A4: 46023 | B4: 0
A5: =A4+1 -> 46024 | B5: 1047.43
A6: =A5+1 -> 46025 | B6: 1099.84
A7: =A6+1 -> 46026 | B7: 799.18
A8: =A7+1 -> 46027 | B8: 1166.82
A9: =A8+1 -> 46028 | B9: 0
A10: =A9+1 -> 46029 | B10: 0
A11: =A10+1 -> 46030 | B11: 179.34
A12: =A11+1 -> 46031 | B12: 1244.21
A13: =A12+1 -> 46032
A14: =A13+1 -> 46033
A15: =A14+1 -> 46034
A16: =A15+1 -> 46035
A17: =A16+1 -> 46036
A18: =A17+1 -> 46037
A19: =A18+1 -> 46038
A20: =A19+1 -> 46039
A21: =A20+1 -> 46040
A22: =A21+1 -> 46041
A23: =A22+1 -> 46042
A24: =A23+1 -> 46043
... A33: =A32+1 -> 46052
A34: =A33+1 -> 46053 | B34: 0
A35: TOTAL GRD | B35: =SUM(B5:B34) -> 5536.82
